Workbook
Name ASME_VIII_division: List!$AP$3:$AP$4
Name Ball_valve: List!$N$2:$N$3
Name BDV: List!$AG$2:$AG$4
Name Bolting_Dia: List!$BG$2:$BG$3
Name Bore: List!$N$2:$N$3
Name Bundle_Type: List!$BC$2:$BC$3
Name Butterfly_valve: List!$N$6
Name Category: List!$BJ$2:$BJ$16
Name Check_valve: List!$N$5
Name Columns: 'Valve Data'!$G$1:$AD$1
Name COST_CAT: 'Cost Type'!$A$2:$A$209
Name CV: List!$AC$2:$AC$4
Name DBB: List!$N$2:$N$3
Name DN: List!$E$2:$E$34
Name DN_0.5: 'Valve Index'!$G$2:$G$101
Name DN_0.75: 'Valve Index'!$H$2:$H$101
Name DN_1: 'Valve Index'!$I$2:$I$101
Name DN_1.5: 'Valve Index'!$J$2:$J$101
Name DN_10: 'Valve Index'!$R$2:$R$101
Name DN_12: 'Valve Index'!$S$2:$S$101
Name DN_14: 'Valve Index'!$T$2:$T$101
Name DN_16: 'Valve Index'!$U$2:$U$101
Name DN_18: 'Valve Index'!$V$2:$V$101
Name DN_2: 'Valve Index'!$K$2:$K$101
Name DN_2.5: 'Valve Index'!$L$2:$L$101
Name DN_20: 'Valve Index'!$W$2:$W$101
Name DN_22: 'Valve Index'!$X$2:$X$101
Name DN_24: 'Valve Index'!$Y$2:$Y$101
Name DN_26: 'Valve Index'!$Z$2:$Z$101
Name DN_28: 'Valve Index'!$AA$2:$AA$101
Name DN_3: 'Valve Index'!$M$2:$M$101
Name DN_30: 'Valve Index'!$AB$2:$AB$101
Name DN_32: 'Valve Index'!$AC$2:$AC$101
Name DN_34: 'Valve Index'!$AD$2:$AD$101
Name DN_36: 'Valve Index'!$AE$2:$AE$101
Name DN_38: 'Valve Index'!$AF$2:$AF$101
Name DN_4: 'Valve Index'!$N$2:$N$101
Name DN_40: 'Valve Index'!$AG$2:$AG$101
Name DN_42: 'Valve Index'!$AH$2:$AH$101
Name DN_5: 'Valve Index'!$O$2:$O$101
Name DN_6: 'Valve Index'!$P$2:$P$101
Name DN_8: 'Valve Index'!$Q$2:$Q$101
Name Equipment_insulation: List!$BM$2:$BM$9
Name ESDV: List!$AI$2:$AI$4
Name FE: List!$Q$2:$Q$5
Name FI: List!$R$2:$R$3
Name Fitting: List!$J$2:$J$8
Name Flange: List!$I$2:$I$3
Name Flange_Face: List!$BI$2:$BI$3
Name Flange_Type: List!$AT$3:$AT$8
Name FT: List!$P$2:$P$12
Name FV: List!$AF$2:$AF$4
Name Gate_valve: List!$N$5
Name Globe_valve: List!$N$5
Name Instrument_type: List!$P$1:$AJ$1
Name Joint_Type: List!$G$2:$G$3
Name LI: List!$T$2:$T$5
Name LT: List!$S$2:$S$12
Name LV: List!$AD$2:$AD$4
Name Material_Code: List!$AO$3:$AO$20

Sheet MCE info
B1: MASTER COST ESTIMATOR v.1.1
A7: Features to be added on the next version
A8: Name of the applicant | B8: feature application description
B9: 1
B10: 2
B11: 3
B12: 4
B13: 5
B14: 6
B15: 7
B16: 8
B17: 9
B18: 10
B19: 11
B20: 12
... B28: 20

Sheet General info
J2: MASTER COST ESTIMATOR
J4: COVER PAGE
A6: 1
A7: 2
A8: 3
A9: 4
A10: 5
A11: 6
A12: 7
A13: 8
A14: 9
A15: 10
A16: 11
A17: 12
... A21: 16
A22: 17 | F22: CLIENT | P22: ANDRITZ
A23: 18
A24: 19 | F24: PROJECT | P24: HYROS
A25: 20
A26: 21 | F26: PROJECT PF No | P26: 10000 NM3/H H2 PDU UNIT
A27: 22
A28: 23 | F28: LOCATION | P28: GERMANY
A29: 24
A30: 25 | F30: DOC. DESCRIPTION | P30: MASTER COST ESTIMATOR
A31: 26
A32: 27 | F32: DOC. PF No
A33: 28
A34: 29
A35: 30
A36: 33
A37: 34
A38: 41
A39: 42
A40: 43
A41: 44
A42: 45
A43: 46
A44: 47
... A55: 58
A56: 59 | B56: 0 | D56: 45606 | H56: Cost revision | U56: AG | Z56: AG | AE56: FR
...

Sheet Notes
A1: 1 | B1: Possibilità di parzializzare il peso a seconda dello skid o se loose
A2: 2 | B2: Verniciatura e Insulation
B3: indicazioni sulla claddatura degli equipment
A5: 3 | B5: 1.1.5.2 | C5: Stainless Steel | F5: ELIMINARE NON SI FANNIO SUPPORTI DIVERSI DA CS
B6: 1.1.5.3 | C6: Duplex Stainless Steel
B7: 1.1.5.4 | C7: Incoloy 825/625
B8: 1.2.5.2 | C8: Stainless Steel
B9: 1.2.5.3 | C9: Duplex Stainless Steel
B10: 1.2.5.4 | C10: Incoloy 825/625
A12: 4 | B12: AGGIUNGERE TE A STRUMENTAZIONE
A13: 5 | B13: AGGIUNGERE VALVOLE CONE ATTUATORI A INSTRUMENT
A14: 6 | B14: evidenziare errore se inserite quantità ma non costo unitario e totale o viceversa
A15: 7 | B15: PSV DOVE LE METTIAMO?
A16: 8 | B16: Montaggio equipment logica su loose o meno
A17: 9 | B17: materiale vessel da piping
A18: 10 | B18: schedule e pesi acciaio inox
A19: 11 | B19: Conteggio n° flange automatico in una finestra come riferimento? Da n° valvole e da n° strumenti
A20: 12 | B20: conteggio bulloneria e guarnizioni (utile per rating alti dal >600#)
A21: 13 | B21: Elenco guarnizioni, bulloni per commissioning (indicare percentuale e pezzi min) solo per equipment MH, HH
A22: 14 | B22: Peso LWN
A23: 15 | B23: Sommario dei segnali strumenti
... A35: 27 | B35: Packing List Completare

Sheet Piping Class
A1: Piping Class
A2: DN | B2: 0.5 | C2: 0.75 | D2: 1 | E2: 1.5 | F2: 2 | G2: 3 | H2: 4 | I2: 6 | J2: 8 | K2: 10 | L2: 12 | M2: 14 | N2: 16 | O2: 18 | P2: 20 | Q2: 24 | R2: 28 | S2: 30 | T2: 32 | U2: 34 | V2: 36 | W2: 38 | X2: 40 | Y2: 42 | Z2: 44
A3: Thickness SCH
A4: CS-150# | B4: 80 | C4: 80 | D4: 80 | E4: 80 | F4: 80 | G4: 40 | H4: 40 | I4: 40 | J4: 20 | K4: 20 | L4: 20 | M4: 20 | N4: 20 | O4: 20 | P4: 20 | Q4: 20 | R4: 10 | S4: 10
A5: SS-300# | B5: 80S | C5: 80S | D5: 80S | E5: 80S | F5: 40S | G5: 40S | H5: 40S | I5: 40 | J5: 40 | K5: 40 | L5: STD | M5: 30 | N5: 40 | O5: XS | P5: 30 | Q5: 40 | R5: 30
A17: Pipe Material
A18: =A4&".piping" -> CS-150#.piping | B18: ASTM 106 Gr.B | C18: ASTM 106 Gr.B | D18: ASTM 106 Gr.B | E18: ASTM 106 Gr.B | F18: ASTM 106 Gr.B | G18: ASTM 106 Gr.B | H18: ASTM 106 Gr.B | I18: ASTM 106 Gr.B | J18: ASTM 106 Gr.B | K18: ASTM 106 Gr.B | L18: ASTM 106 Gr.B | M18: ASTM 106 Gr.B | N18: ASTM 106 Gr.B | O18: ASTM 106 Gr.B | P18: ASTM 106 Gr.B | Q18: ASTM 106 Gr.B | R18: ASTM A672 Gr C60 Cl.12 | S18: ASTM A672 Gr C60 Cl.12
A19: =A5&".piping" -> SS-300#.piping | B19: ASTM A312- TP316/316L | C19: ASTM A312- TP316/316L | D19: ASTM A312- TP316/316L | E19: ASTM A312- TP316/316L | F19: ASTM A312- TP316/316L | G19: ASTM A312- TP316/316L | H19: ASTM A312- TP316/316L | I19: ASTM A312- TP316/316L | J19: ASTM A312- TP316/316L | K19: ASTM A312- TP316/316L | L19: ASTM A312- TP316/316L | M19: ASTM A312- TP316/316L | N19: ASTM A312- TP316/316L | O19: ASTM A312- TP316/316L | P19: ASTM A312- TP316/316L | Q19: ASTM A312- TP316/316L | R19: ASTM A672 Gr C60 Cl.12 | S19: ASTM A672 Gr C60 Cl.12
A20: =A6&".piping" -> .piping
A21: =A7&".piping" -> .piping
A22: =A8&".piping" -> .piping
A23: =A9&".piping" -> .piping
A24: =A10&".piping" -> .piping
A25: =A11&".piping" -> .piping
A26: =A12&".piping" -> .piping
A27: =A13&".piping" -> .piping
A28: =A14&".piping" -> .piping
A29: =A15&".piping" -> .piping
A30: =A16&".piping" -> .piping
A31: Fitting Material
A32: =A4&".fitting" -> CS-150#.fitting | B32: ASTM 106 Gr.B | C32: ASTM 106 Gr.B | D32: ASTM 106 Gr.B | E32: ASTM 106 Gr.B | F32: ASTM 106 Gr.B | G32: ASTM 106 Gr.B | H32: ASTM 106 Gr.B | I32: ASTM 106 Gr.B | J32: ASTM 106 Gr.B | K32: ASTM 106 Gr.B | L32: ASTM 106 Gr.B | M32: ASTM 106 Gr.B | N32: ASTM 106 Gr.B | O32: ASTM 106 Gr.B | P32: ASTM 106 Gr.B | Q32: ASTM 106 Gr.B | R32: ASTM A672 Gr C60 Cl.12 | S32: ASTM A672 Gr C60 Cl.12
A33: =A5&".fitting" -> SS-300#.fitting | B33: ASTM A312- TP316/316L | C33: ASTM A312- TP316/316L | D33: ASTM A312- TP316/316L | E33: ASTM A312- TP316/316L | F33: ASTM A312- TP316/316L | G33: ASTM A312- TP316/316L | H33: ASTM A312- TP316/316L | I33: ASTM A312- TP316/316L | J33: ASTM A312- TP316/316L | K33: ASTM A312- TP316/316L | L33: ASTM A312- TP316/316L | M33: ASTM A312- TP316/316L | N33: ASTM A312- TP316/316L | O33: ASTM A312- TP316/316L | P33: ASTM A312- TP316/316L | Q33: ASTM A312- TP316/316L | R33: ASTM A672 Gr C60 Cl.12 | S33: ASTM A672 Gr C60 Cl.12
A34: =A6&".fitting" -> .fitting
A35: =A7&".fitting" -> .fitting
A36: =A8&".fitting" -> .fitting
A37: =A9&".fitting" -> .fitting
A38: =A10&".fitting" -> .fitting
A39: =A11&".fitting" -> .fitting
A40: =A12&".fitting" -> .fitting
A41: =A13&".fitting" -> .fitting
A42: =A14&".fitting" -> .fitting
A43: =A15&".fitting" -> .fitting
A44: =A16&".fitting" -> .fitting
A45: Flange Material
A46: =A4&".flange" -> CS-150#.flange | B46: ASTM 106 Gr.B | C46: ASTM 106 Gr.B | D46: ASTM 106 Gr.B | E46: ASTM 106 Gr.B | F46: ASTM 106 Gr.B | G46: ASTM 106 Gr.B | H46: ASTM 106 Gr.B | I46: ASTM 106 Gr.B | J46: ASTM 106 Gr.B | K46: ASTM 106 Gr.B | L46: ASTM 106 Gr.B | M46: ASTM 106 Gr.B | N46: ASTM 106 Gr.B | O46: ASTM 106 Gr.B | P46: ASTM 106 Gr.B | Q46: ASTM 106 Gr.B | R46: ASTM A672 Gr C60 Cl.12 | S46: ASTM A672 Gr C60 Cl.12
A47: =A5&".flange" -> SS-300#.flange | B47: ASTM A312- TP316/316L | C47: ASTM A312- TP316/316L | D47: ASTM A312- TP316/316L | E47: ASTM A312- TP316/316L | F47: ASTM A312- TP316/316L | G47: ASTM A312- TP316/316L | H47: ASTM A312- TP316/316L | I47: ASTM A312- TP316/316L | J47: ASTM A312- TP316/316L | K47: ASTM A312- TP316/316L | L47: ASTM A312- TP316/316L | M47: ASTM A312- TP316/316L | N47: ASTM A312- TP316/316L | O47: ASTM A312- TP316/316L | P47: ASTM A312- TP316/316L | Q47: ASTM A312- TP316/316L | R47: ASTM A672 Gr C60 Cl.12 | S47: ASTM A672 Gr C60 Cl.12
A48: =A6&".flange" -> .flange
A49: =A7&".flange" -> .flange
A50: =A8&".flange" -> .flange
A51: =A9&".flange" -> .flange
...

Sheet Valve Data
A1: Index | B1: Valve Type | C1: Piping Class | D1: Bore (for Ball Valve only) | E1: DN min | F1: DN max | G1: Rating | H1: Construction Code | I1: Body Contruction | J1: Valve Description | K1: Body Material | L1: Trim Matrial | M1: Ends Type | N1: Ends Face | O1: Trunnion / Floating | P1: Gear / Lever / Handwheel Operated | Q1: Seat Type / Material | R1: Packing Type / Material | S1: NACE MR0175/ISO 15156 | T1: Sour Service | U1: Lethal Service | V1: Material Certification EN10204 | W1: Disc Type | X1: Disc Material | Y1: C.A. [mm] | Z1: Fire Safe | AA1: Packing Type / Material | AB1: Material Group | AC1: NOTE 1 | AD1: NOTE 2
A2: 1 | B2: Ball_valve | C2: CS-150# | D2: RB | E2: 0.5 | F2: 1.5 | G2: =IFERROR(VLOOKUP(C2,'Piping Class'!$90:$102,2,0),"") -> 150 | H2: ISO 14313 / API 608 | I2: Split Body | K2: A105 | L2: F316 | M2: Flange | N2: RF | O2: Floating | P2: Lever | Q2: R-PTFE | R2: Graphite | S2: YES | T2: NO | U2: NO | V2: 3.1 | Y2: 3 | Z2: API 608 / ISO 10497 | AB2: =IFERROR(VLOOKUP(C2,'Piping Class'!$90:$102,7,0),"") -> CS
A3: 28 | B3: Ball_valve | C3: CS-150# | D3: RB | E3: 1 | F3: 6 | G3: =IFERROR(VLOOKUP(C3,'Piping Class'!$90:$102,2,0),"") -> 150 | H3: ISO 14313 / API 608 | I3: Split Body | K3: A105 | L3: F316 | M3: Flange | N3: RF | O3: Floating | P3: Lever | Q3: R-PTFE | R3: Graphite | S3: YES | T3: NO | U3: NO | V3: 3.1 | Y3: 3 | Z3: API 608 / ISO 10497 | AB3: =IFERROR(VLOOKUP(C3,'Piping Class'!$90:$102,7,0),"") -> CS
A4: 6 | B4: Ball_valve | C4: CS-150# | D4: RB | E4: 8 | F4: 24 | G4: =IFERROR(VLOOKUP(C4,'Piping Class'!$90:$102,2,0),"") -> 150 | H4: ISO 14313 / API 608 | I4: Split Body | K4: A105 | L4: F316 | M4: Flange | N4: RF | O4: Floating | P4: Lever | Q4: R-PTFE | R4: Graphite | S4: YES | T4: NO | U4: NO | V4: 3.1 | Y4: 3 | Z4: API 608 / ISO 10497 | AB4: =IFERROR(VLOOKUP(C4,'Piping Class'!$90:$102,7,0),"") -> CS
A5: 15 | B5: Check_valve | C5: CS-150# | E5: 0.5 | F5: 24 | G5: =IFERROR(VLOOKUP(C5,'Piping Class'!$90:$102,2,0),"") -> 150 | H5: ISO 15761/API 602 | K5: A216 WCB | M5: Flange | N5: RF | S5: YES | T5: NO | U5: NO | V5: 3.1 | X5: AISI 316 | Y5: 0 | Z5: API 608 / ISO 10497 | AB5: =IFERROR(VLOOKUP(C5,'Piping Class'!$90:$102,7,0),"") -> CS
A6: 2 | B6: Globe_valve | C6: CS-150# | E6: 0.5 | F6: 24 | G6: =IFERROR(VLOOKUP(C6,'Piping Class'!$90:$102,2,0),"") -> 150 | H6: ISO 14313 / API 611 | K6: A216 WCB | L6: F316 | M6: Flange | N6: RF | P6: Handwheel | Q6: R-PTFE | R6: Graphite | S6: YES | T6: NO | U6: NO | V6: 3.1 | Y6: 3 | Z6: API 608 / ISO 10497 | AB6: =IFERROR(VLOOKUP(C6,'Piping Class'!$90:$102,7,0),"") -> CS
A7: 5 | B7: Gate_valve | C7: CS-150# | E7: 0.5 | F7: 24 | G7: =IFERROR(VLOOKUP(C7,'Piping Class'!$90:$102,2,0),"") -> 150 | H7: ISO 14313 / API 611 | K7: A216 WCB | L7: F316 | M7: Flange | N7: RF | P7: Handwheel | Q7: R-PTFE | R7: Graphite | S7: YES | T7: NO | U7: NO | V7: 3.1 | Y7: 3 | Z7: API 608 / ISO 10497 | AB7: =IFERROR(VLOOKUP(C7,'Piping Class'!$90:$102,7,0),"") -> CS
A8: 10 | G8: =IFERROR(VLOOKUP(C8,'Piping Class'!$90:$102,2,0),"") | AB8: =IFERROR(VLOOKUP(C8,'Piping Class'!$90:$102,7,0),"")
A9: 19 | B9: DBB | C9: SS-600# | E9: 0.5 | F9: 3 | G9: =IFERROR(VLOOKUP(C9,'Piping Class'!$90:$102,2,0),"") | H9: ISO 14313 / API 608 | I9: Split Body | K9: AISI 316L | L9: F316 | M9: Flange | N9: RF | O9: Floating | P9: Lever | Q9: R-PTFE | R9: Graphite | S9: YES | T9: NO | U9: NO | V9: 3.1 | Y9: 3 | Z9: API 608 / ISO 10497 | AB9: =IFERROR(VLOOKUP(C9,'Piping Class'!$90:$102,7,0),"")
A10: 16 | G10: =IFERROR(VLOOKUP(C10,'Piping Class'!$90:$102,2,0),"") | AB10: =IFERROR(VLOOKUP(C10,'Piping Class'!$90:$102,7,0),"")
A11: 7 | B11: Ball_valve | C11: SS-600# | D11: RB | E11: 0.5 | F11: 1.5 | G11: =IFERROR(VLOOKUP(C11,'Piping Class'!$90:$102,2,0),"") | H11: ISO 14313 / API 608 | I11: Split Body | K11: AISI 316L | L11: F316 | M11: Flange | N11: RF | O11: Floating | P11: Lever | Q11: R-PTFE | R11: Graphite | S11: YES | T11: NO | U11: NO | V11: 3.1 | X11: AISI 316 | Y11: 0 | Z11: API 608 / ISO 10497 | AB11: =IFERROR(VLOOKUP(C11,'Piping Class'!$90:$102,7,0),"")
A12: 11 | B12: Ball_valve | C12: SS-600# | D12: RB | E12: 1 | F12: 6 | G12: =IFERROR(VLOOKUP(C12,'Piping Class'!$90:$102,2,0),"") | H12: ISO 14313 / API 608 | I12: Split Body | K12: AISI 316L | L12: F316 | M12: Flange | N12: RF | O12: Floating | P12: Lever | Q12: R-PTFE | R12: Graphite | S12: YES | T12: NO | U12: NO | V12: 3.1 | X12: AISI 316 | Y12: 0 | Z12: API 608 / ISO 10497 | AB12: =IFERROR(VLOOKUP(C12,'Piping Class'!$90:$102,7,0),"")
A13: 14 | B13: Ball_valve | C13: SS-600# | D13: RB | E13: 8 | F13: 24 | G13: =IFERROR(VLOOKUP(C13,'Piping Class'!$90:$102,2,0),"") | H13: ISO 14313 / API 608 | I13: Split Body | K13: AISI 316L | L13: F316 | M13: Flange | N13: RF | O13: Floating | P13: Lever | Q13: R-PTFE | R13: Graphite | S13: YES | T13: NO | U13: NO | V13: 3.1 | Y13: 3 | Z13: API 608 / ISO 10497 | AB13: =IFERROR(VLOOKUP(C13,'Piping Class'!$90:$102,7,0),"")
A14: 26 | B14: Check_valve | C14: SS-600# | E14: 0.5 | F14: 24 | G14: =IFERROR(VLOOKUP(C14,'Piping Class'!$90:$102,2,0),"") | H14: ISO 15761/API 602 | K14: AISI 316L | M14: Flange | N14: RF | S14: YES | T14: NO | U14: NO | V14: 3.1 | X14: AISI 316 | Y14: 0 | Z14: API 608 / ISO 10497 | AB14: =IFERROR(VLOOKUP(C14,'Piping Class'!$90:$102,7,0),"")
A15: 20 | B15: Globe_valve | C15: SS-600# | E15: 0.5 | F15: 24 | G15: =IFERROR(VLOOKUP(C15,'Piping Class'!$90:$102,2,0),"") | H15: ISO 14313 / API 611 | K15: AISI 316L | L15: F316 | M15: Flange | N15: RF | P15: Handwheel | Q15: R-PTFE | R15: Graphite | S15: YES | T15: NO | U15: NO | V15: 3.1 | Y15: 3 | Z15: API 608 / ISO 10497 | AB15: =IFERROR(VLOOKUP(C15,'Piping Class'!$90:$102,7,0),"")
A16: 22 | B16: Gate_valve | C16: SS-600# | E16: 0.5 | F16: 24 | G16: =IFERROR(VLOOKUP(C16,'Piping Class'!$90:$102,2,0),"") | H16: ISO 14313 / API 611 | K16: AISI 316L | L16: F316 | M16: Flange | N16: RF | P16: Handwheel | Q16: R-PTFE | R16: Graphite | S16: YES | T16: NO | U16: NO | V16: 3.1 | Y16: 3 | Z16: API 608 / ISO 10497 | AB16: =IFERROR(VLOOKUP(C16,'Piping Class'!$90:$102,7,0),"")
A17: 24 | G17: =IFERROR(VLOOKUP(C17,'Piping Class'!$90:$102,2,0),"") | AB17: =IFERROR(VLOOKUP(C17,'Piping Class'!$90:$102,7,0),"")
A18: 3 | B18: DBB | C18: CS-900# | E18: 0.5 | F18: 3 | G18: =IFERROR(VLOOKUP(C18,'Piping Class'!$90:$102,2,0),"") | H18: ISO 14313 / API 608 | I18: Split Body | K18: A105 | L18: F316 | M18: Flange | N18: RF | O18: Floating | P18: Lever | Q18: R-PTFE | R18: Graphite | S18: YES | T18: NO | U18: NO | V18: 3.1 | Y18: 3 | Z18: API 608 / ISO 10497 | AB18: =IFERROR(VLOOKUP(C18,'Piping Class'!$90:$102,7,0),"")
A19: 4 | G19: =IFERROR(VLOOKUP(C19,'Piping Class'!$90:$102,2,0),"") | AB19: =IFERROR(VLOOKUP(C19,'Piping Class'!$90:$102,7,0),"")
A20: 8 | B20: Ball_valve | C20: SS-300# | D20: RB | E20: 0.5 | F20: 1.5 | G20: =IFERROR(VLOOKUP(C20,'Piping Class'!$90:$102,2,0),"") -> 300 | H20: ISO 14313 / API 608 | I20: Split Body | K20: AISI 316L | L20: F316 | M20: Flange | N20: RF | O20: Floating | P20: Lever | Q20: R-PTFE | R20: Graphite | S20: YES | T20: NO | U20: NO | V20: 3.1 | Y20: 3 | Z20: API 608 / ISO 10497 | AB20: =IFERROR(VLOOKUP(C20,'Piping Class'!$90:$102,7,0),"") -> SS
A21: 9 | B21: Ball_valve | C21: SS-300# | D21: RB | E21: 2 | F21: 6 | G21: =IFERROR(VLOOKUP(C21,'Piping Class'!$90:$102,2,0),"") -> 300 | H21: ISO 14313 / API 608 | I21: Split Body | K21: AISI 316L | L21: F316 | M21: Flange | N21: RF | O21: Trunion | P21: Lever | Q21: R-PTFE | R21: Graphite | S21: YES | T21: NO | U21: NO | V21: 3.1 | Y21: 3 | Z21: API 608 / ISO 10497 | AB21: =IFERROR(VLOOKUP(C21,'Piping Class'!$90:$102,7,0),"") -> SS
A22: 12 | B22: Ball_valve | C22: SS-300# | D22: RB | E22: 8 | F22: 24 | G22: =IFERROR(VLOOKUP(C22,'Piping Class'!$90:$102,2,0),"") -> 300 | H22: ISO 14313 / API 608 | I22: Split Body | K22: AISI 316L | L22: F316 | M22: Flange | N22: RF | O22: Trunion | P22: gear | Q22: R-PTFE | R22: Graphite | S22: YES | T22: NO | U22: NO | V22: 3.1 | Y22: 3 | Z22: API 608 / ISO 10497 | AB22: =IFERROR(VLOOKUP(C22,'Piping Class'!$90:$102,7,0),"") -> SS
A23: 13 | B23: Check_valve | C23: SS-300# | E23: 0.5 | F23: 24 | G23: =IFERROR(VLOOKUP(C23,'Piping Class'!$90:$102,2,0),"") -> 300 | H23: ISO 15761/API 602 | K23: AISI 316L | M23: Flange | N23: RF | S23: YES | T23: NO | U23: NO | V23: 3.1 | X23: AISI 316 | Y23: 3 | Z23: API 608 / ISO 10497 | AB23: =IFERROR(VLOOKUP(C23,'Piping Class'!$90:$102,7,0),"") -> SS
A24: 27 | B24: Globe_valve | C24: SS-150# | E24: 0.5 | F24: 24 | G24: =IFERROR(VLOOKUP(C24,'Piping Class'!$90:$102,2,0),"") | H24: ISO 14313 / API 611 | K24: AISI 316L | L24: F316 | M24: Flange | N24: RF | P24: Handwheel | Q24: R-PTFE | R24: Graphite | S24: YES | T24: NO | U24: NO | V24: 3.1 | Y24: 3 | Z24: API 608 / ISO 10497 | AB24: =IFERROR(VLOOKUP(C24,'Piping Class'!$90:$102,7,0),"")
A25: 17 | B25: Gate_valve | C25: SS-150# | E25: 0.5 | F25: 24 | G25: =IFERROR(VLOOKUP(C25,'Piping Class'!$90:$102,2,0),"") | H25: ISO 14313 / API 611 | K25: AISI 316L | L25: F316 | M25: Flange | N25: RF | P25: Handwheel | Q25: R-PTFE | R25: Graphite | S25: YES | T25: NO | U25: NO | V25: 3.1 | Y25: 3 | Z25: API 608 / ISO 10497 | AB25: =IFERROR(VLOOKUP(C25,'Piping Class'!$90:$102,7,0),"")
A26: 18 | G26: =IFERROR(VLOOKUP(C26,'Piping Class'!$90:$102,2,0),"") | AB26: =IFERROR(VLOOKUP(C26,'Piping Class'!$90:$102,7,0),"")
A27: 21 | B27: DBB | C27: SS-150# | E27: 0.5 | F27: 3 | G27: =IFERROR(VLOOKUP(C27,'Piping Class'!$90:$102,2,0),"") | H27: ISO 14313 / API 608 | I27: Split Body | K27: AISI 316L | L27: F316 | M27: Flange | N27: RF | O27: Floating | P27: Lever | Q27: R-PTFE | R27: Graphite | S27: YES | T27: NO | U27: NO | V27: 3.1 | Y27: 3 | Z27: API 608 / ISO 10497 | AB27: =IFERROR(VLOOKUP(C27,'Piping Class'!$90:$102,7,0),"")
A28: 23 | G28: =IFERROR(VLOOKUP(C28,'Piping Class'!$90:$102,2,0),"") | AB28: =IFERROR(VLOOKUP(C28,'Piping Class'!$90:$102,7,0),"")
A29: 25 | B29: Ball_valve | C29: SS-900# | D29: RB | E29: 0.5 | F29: 1.5 | G29: =IFERROR(VLOOKUP(C29,'Piping Class'!$90:$102,2,0),"") | H29: ISO 14313 / API 608 | I29: Split Body | K29: AISI 316L | L29: F316 | M29: Flange | N29: RF | O29: Floating | P29: Lever | Q29: R-PTFE | R29: Graphite | S29: YES | T29: NO | U29: NO | V29: 3.1 | Y29: 3 | Z29: API 608 / ISO 10497 | AB29: =IFERROR(VLOOKUP(C29,'Piping Class'!$90:$102,7,0),"")
A30: 29 | B30: Ball_valve | C30: SS-900# | D30: RB | E30: 2 | F30: 6 | G30: =IFERROR(VLOOKUP(C30,'Piping Class'!$90:$102,2,0),"") | H30: ISO 14313 / API 608 | I30: Split Body | K30: AISI 316L | L30: F316 | M30: Flange | N30: RF | O30: Trunion | P30: Lever | Q30: R-PTFE | R30: Graphite | S30: YES | T30: NO | U30: NO | V30: 3.1 | Y30: 3 | Z30: API 608 / ISO 10497 | AB30: =IFERROR(VLOOKUP(C30,'Piping Class'!$90:$102,7,0),"")
A31: 30 | B31: Ball_valve | C31: SS-900# | D31: RB | E31: 8 | F31: 24 | G31: =IFERROR(VLOOKUP(C31,'Piping Class'!$90:$102,2,0),"") | H31: ISO 14313 / API 608 | I31: Split Body | K31: AISI 316L | L31: F316 | M31: Flange | N31: RF | O31: Trunion | P31: gear | Q31: R-PTFE | R31: Graphite | S31: YES | T31: NO | U31: NO | V31: 3.1 | Y31: 3 | Z31: API 608 / ISO 10497 | AB31: =IFERROR(VLOOKUP(C31,'Piping Class'!$90:$102,7,0),"")
A32: 31 | B32: Check_valve | C32: SS-900# | E32: 0.5 | F32: 24 | G32: =IFERROR(VLOOKUP(C32,'Piping Class'!$90:$102,2,0),"") | H32: ISO 15761/API 602 | K32: AISI 316L | M32: Flange | N32: RF | S32: YES | T32: NO | U32: NO | V32: 3.1 | X32: AISI 316 | Y32: 3 | Z32: API 608 / ISO 10497 | AB32: =IFERROR(VLOOKUP(C32,'Piping Class'!$90:$102,7,0),"")
A33: 32 | B33: Globe_valve | C33: SS-900# | E33: 0.5 | F33: 24 | G33: =IFERROR(VLOOKUP(C33,'Piping Class'!$90:$102,2,0),"") | H33: ISO 14313 / API 611 | K33: AISI 316L | L33: F316 | M33: Flange | N33: RF | P33: Handwheel | Q33: R-PTFE | R33: Graphite | S33: YES | T33: NO | U33: NO | V33: 3.1 | Y33: 3 | Z33: API 608 / ISO 10497 | AB33: =IFERROR(VLOOKUP(C33,'Piping Class'!$90:$102,7,0),"")
A34: 33 | B34: Gate_valve | C34: CS-900# | E34: 0.5 | F34: 24 | G34: =IFERROR(VLOOKUP(C34,'Piping Class'!$90:$102,2,0),"") | H34: ISO 14313 / API 611 | K34: A216 WCB | L34: F316 | M34: Flange | N34: RF | P34: Handwheel | Q34: R-PTFE | R34: Graphite | S34: YES | T34: NO | U34: NO | V34: 3.1 | Y34: 3 | Z34: API 608 / ISO 10497 | AB34: =IFERROR(VLOOKUP(C34,'Piping Class'!$90:$102,7,0),"")
A35: 34 | G35: =IFERROR(VLOOKUP(C35,'Piping Class'!$90:$102,2,0),"") | AB35: =IFERROR(VLOOKUP(C35,'Piping Class'!$90:$102,7,0),"")
A36: 35 | B36: DBB | C36: CS-150# | E36: 0.5 | F36: 3 | G36: =IFERROR(VLOOKUP(C36,'Piping Class'!$90:$102,2,0),"") -> 150 | H36: ISO 14313 / API 608 | I36: Split Body | K36: A105 | L36: F316 | M36: Flange | N36: RF | O36: Floating | P36: Lever | Q36: R-PTFE | R36: Graphite | S36: YES | T36: NO | U36: NO | V36: 3.1 | Y36: 3 | Z36: API 608 / ISO 10497 | AB36: =IFERROR(VLOOKUP(C36,'Piping Class'!$90:$102,7,0),"") -> CS
A37: 36 | B37: SBB | C37: SS-900# | E37: 0.5 | F37: 3 | G37: =IFERROR(VLOOKUP(C37,'Piping Class'!$90:$102,2,0),"") | H37: ISO 14313 / API 608 | I37: Split Body | K37: AISI 316L | L37: F316 | M37: Flange | N37: RF | O37: Floating | P37: Lever | Q37: R-PTFE | R37: Graphite | S37: YES | T37: NO | U37: NO | V37: 3.1 | Y37: 3 | Z37: API 608 / ISO 10497 | AB37: =IFERROR(VLOOKUP(C37,'Piping Class'!$90:$102,7,0),"")
A38: 37 | G38: =IFERROR(VLOOKUP(C38,'Piping Class'!$90:$102,2,0),"") | AB38: =IFERROR(VLOOKUP(C38,'Piping Class'!$90:$102,7,0),"")
A39: 38 | B39: Globe_valve | C39: SS-150# | E39: 0.5 | F39: 24 | G39: =IFERROR(VLOOKUP(C39,'Piping Class'!$90:$102,2,0),"") | H39: ISO 14313 / API 611 | K39: AISI 316L | L39: F316 | M39: Flange | N39: RF | P39: Handwheel | Q39: R-PTFE | R39: Graphite | S39: YES | T39: NO | U39: NO | V39: 3.1 | Y39: 3 | Z39: API 608 / ISO 10497 | AB39: =IFERROR(VLOOKUP(C39,'Piping Class'!$90:$102,7,0),"")
A40: 39 | B40: Globe_valve | C40: CS-150# | E40: 0.5 | F40: 24 | G40: =IFERROR(VLOOKUP(C40,'Piping Class'!$90:$102,2,0),"") -> 150 | H40: ISO 14313 / API 611 | K40: A216 WCB | L40: F316 | M40: Flange | N40: RF | P40: Handwheel | Q40: R-PTFE | R40: Graphite | S40: YES | T40: NO | U40: NO | V40: 3.1 | Y40: 3 | Z40: API 608 / ISO 10497 | AB40: =IFERROR(VLOOKUP(C40,'Piping Class'!$90:$102,7,0),"") -> CS
...

Sheet Equipment Weight Calc
A1: EQUIPMENT WEIGHT CALCULATION | K1: Extraction
A2: ="POS."&K2&" "&VLOOKUP(K2,'Equip&Mach List'!$1:$1048576,2,0)&" "&VLOOKUP(K2,'Equip&Mach List'!$1:$1048576,3,0) -> POS.1 R-201 Deoxo reactor | I2: =IFERROR("Weight Calc./Selected = "&ROUND(B119,1)&"/"&B120&" kg - Øi ="&IF(B26=0,F26,B26)&" mm"&"T/T ="&IF(B28=0,F28,B28)&" mm - Material "&B13&" ","") -> Weight Calc./Selected = 2290,5/2300 kg - Øi =800 mmT/T =2100 mm - Material SA-240 Gr.316L | K2: 1
K3: Design Code | L3: =K2&"."&K3 -> 1.Design Code | M3: =A4&" "&B4 -> ASME VIII div.1
A4: ASME VIII | B4: div.1 | K4: Orientation | L4: =K2&"."&K4 -> 1.Orientation | M4: =B5 -> Vertical
A5: Vessel Orientation | B5: Vertical | K5: Design Temperature | L5: =K2&"."&K5 -> 1.Design Temperature | M5: =D8 -> 350
K6: Design Pressure | L6: =K2&"."&K6 -> 1.Design Pressure | M6: =D9 -> 18
A7: Design Data: | K7: Material | L7: =K2&"."&K7 -> 1.Material | M7: =B13 -> SA-240 Gr.316L
A8: Temperature | B8: 350 | C8: °C | D8: =IF(C8="°C",B8,0)+IF(C8="°F",(B8-32)*5/9,0) -> 350 | E8: °C | K8: Inside Diameter | L8: =K2&"."&K8 -> 1.Inside Diameter | M8: =IF(B26=0,F26,B26) -> 800
A9: Internal Pressure | B9: 18 | C9: barg | D9: =IF(C9="barg",B9,0)+IF(C9="psig",B9*List!$AV$4,0)+IF(C9="MPa",B9*List!$AV$5,0)+IF(C9="N/mm2",B9*List!$AV$6,0) -> 18 | E9: barg | K9: Tan / Tan | L9: =K2&"."&K9 -> 1.Tan / Tan | M9: =IF(B28=0,F28,B28) -> 2100
A10: External Pressure | B10: 0 | C10: barg | D10: =IF(C10="barg",B10,0)+IF(C10="psig",B10*List!$AV$4,0)+IF(C10="MPa",B10*List!$AV$5,0)+IF(C10="N/mm2",B10*List!$AV$6,0) -> 0 | E10: barg | K10: Thickness | L10: =K2&"."&K10 -> 1.Thickness | M10: =IF(B67=0,F71,B67) -> 12
K11: Unit Weight | L11: =K2&"."&K11 -> 1.Unit Weight | M11: =B120 -> 2300
A12: Material Selection: | B12: from plate | F12: from piping | K12: Unit External Surface | L12: =K2&"."&K12 -> 1.Unit External Surface | M12: =B116 -> 17.282932
A13: Shell | B13: SA-240 Gr.316L | K13: M1 DN | L13: =K2&"."&K13 -> 1.M1 DN | M13: =C134 -> 0
A14: Head | B14: SA-240 Gr.316L | K14: M1 Rating | L14: =K2&"."&K14 -> 1.M1 Rating | M14: =D134 -> 0
K15: M1 Type | L15: =K2&"."&K15 -> 1.M1 Type | M15: =E134 -> 0
A16: ASME VIII div.1 | K16: M1 Quantity | L16: =K2&"."&K16 -> 1.M1 Quantity | M16: =F134 -> 0
A17: Maximum Allowable Stress Shell | B17: =$D8*(VLOOKUP($B13,'ASME II Tab 1A'!$1:$1048576,MATCH($D8,'ASME II Tab 1A'!$6:$6,1)+1,0)-VLOOKUP($B13,'ASME II Tab 1A'!$1:$1048576,MATCH($D8,'ASME II Tab 1A'!$6:$6,1),0))/(INDEX('ASME II Tab 1A'!$6:$6,MATCH($D8,'ASME II Tab 1A'!$6:$6,1)+1)-INDEX('ASME II Tab 1A'!$6:$6,MATCH($D8,'ASME II Tab 1A'!$6:$6,1)))+VLOOKUP($B13,'ASME II Tab 1A'!$1:$1048576,MATCH($D8,'ASME II Tab 1A'!$6:$6,1)+1,0)-INDEX('ASME II Tab 1A'!$6:$6,MATCH($D8,'ASME II Tab 1A'!$6:$6,1)+1)*(VLOOKUP($B13,'ASME II Tab 1A'!$1:$1048576,MATCH($D8,'ASME II Tab 1A'!$6:$6,1)+1,0)-VLOOKUP($B13,'ASME II Tab 1A'!$1:$1048576,MATCH($D8,'ASME II Tab 1A'!$6:$6,1),0))/(INDEX('ASME II Tab 1A'!$6:$6,MATCH($D8,'ASME II Tab 1A'!$6:$6,1)+1)-INDEX('ASME II Tab 1A'!$6:$6,MATCH($D8,'ASME II Tab 1A'!$6:$6,1))) -> 94.1 | C17: N/mm2 | F17: =$D8*(VLOOKUP($F13,'ASME II Tab 1A'!$1:$1048576,MATCH($D8,'ASME II Tab 1A'!$6:$6,1)+1,0)-VLOOKUP($F13,'ASME II Tab 1A'!$1:$1048576,MATCH($D8,'ASME II Tab 1A'!$6:$6,1),0))/(INDEX('ASME II Tab 1A'!$6:$6,MATCH($D8,'ASME II Tab 1A'!$6:$6,1)+1)-INDEX('ASME II Tab 1A'!$6:$6,MATCH($D8,'ASME II Tab 1A'!$6:$6,1)))+VLOOKUP($F13,'ASME II Tab 1A'!$1:$1048576,MATCH($D8,'ASME II Tab 1A'!$6:$6,1)+1,0)-INDEX('ASME II Tab 1A'!$6:$6,MATCH($D8,'ASME II Tab 1A'!$6:$6,1)+1)*(VLOOKUP($F13,'ASME II Tab 1A'!$1:$1048576,MATCH($D8,'ASME II Tab 1A'!$6:$6,1)+1,0)-VLOOKUP($F13,'ASME II Tab 1A'!$1:$1048576,MATCH($D8,'ASME II Tab 1A'!$6:$6,1),0))/(INDEX('ASME II Tab 1A'!$6:$6,MATCH($D8,'ASME II Tab 1A'!$6:$6,1)+1)-INDEX('ASME II Tab 1A'!$6:$6,MATCH($D8,'ASME II Tab 1A'!$6:$6,1))) -> #N/A | G17: N/mm2 | K17: M2 DN | L17: =K2&"."&K17 -> 1.M2 DN | M17: =C135 -> 0
A18: Maximum Allowable Stress Head | B18: =$D8*(VLOOKUP($B14,'ASME II Tab 1A'!$1:$1048576,MATCH($D8,'ASME II Tab 1A'!$6:$6,1)+1,0)-VLOOKUP($B14,'ASME II Tab 1A'!$1:$1048576,MATCH($D8,'ASME II Tab 1A'!$6:$6,1),0))/(INDEX('ASME II Tab 1A'!$6:$6,MATCH($D8,'ASME II Tab 1A'!$6:$6,1)+1)-INDEX('ASME II Tab 1A'!$6:$6,MATCH($D8,'ASME II Tab 1A'!$6:$6,1)))+VLOOKUP($B14,'ASME II Tab 1A'!$1:$1048576,MATCH($D8,'ASME II Tab 1A'!$6:$6,1)+1,0)-INDEX('ASME II Tab 1A'!$6:$6,MATCH($D8,'ASME II Tab 1A'!$6:$6,1)+1)*(VLOOKUP($B14,'ASME II Tab 1A'!$1:$1048576,MATCH($D8,'ASME II Tab 1A'!$6:$6,1)+1,0)-VLOOKUP($B14,'ASME II Tab 1A'!$1:$1048576,MATCH($D8,'ASME II Tab 1A'!$6:$6,1),0))/(INDEX('ASME II Tab 1A'!$6:$6,MATCH($D8,'ASME II Tab 1A'!$6:$6,1)+1)-INDEX('ASME II Tab 1A'!$6:$6,MATCH($D8,'ASME II Tab 1A'!$6:$6,1))) -> 94.1 | C18: N/mm2 | F18: =$D8*(VLOOKUP($F14,'ASME II Tab 1A'!$1:$1048576,MATCH($D8,'ASME II Tab 1A'!$6:$6,1)+1,0)-VLOOKUP($F14,'ASME II Tab 1A'!$1:$1048576,MATCH($D8,'ASME II Tab 1A'!$6:$6,1),0))/(INDEX('ASME II Tab 1A'!$6:$6,MATCH($D8,'ASME II Tab 1A'!$6:$6,1)+1)-INDEX('ASME II Tab 1A'!$6:$6,MATCH($D8,'ASME II Tab 1A'!$6:$6,1)))+VLOOKUP($F14,'ASME II Tab 1A'!$1:$1048576,MATCH($D8,'ASME II Tab 1A'!$6:$6,1)+1,0)-INDEX('ASME II Tab 1A'!$6:$6,MATCH($D8,'ASME II Tab 1A'!$6:$6,1)+1)*(VLOOKUP($F14,'ASME II Tab 1A'!$1:$1048576,MATCH($D8,'ASME II Tab 1A'!$6:$6,1)+1,0)-VLOOKUP($F14,'ASME II Tab 1A'!$1:$1048576,MATCH($D8,'ASME II Tab 1A'!$6:$6,1),0))/(INDEX('ASME II Tab 1A'!$6:$6,MATCH($D8,'ASME II Tab 1A'!$6:$6,1)+1)-INDEX('ASME II Tab 1A'!$6:$6,MATCH($D8,'ASME II Tab 1A'!$6:$6,1))) -> #N/A | G18: N/mm2 | K18: M2 Rating | L18: =K2&"."&K18 -> 1.M2 Rating | M18: =D135 -> 0
A19: ASME VIII div.2 | K19: M2 Type | L19: =K2&"."&K19 -> 1.M2 Type | M19: =E135 -> 0
A20: Maximum Allowable Stress Shell | B20: =$D8*(VLOOKUP($B13,'ASME II Tab 5A'!$1:$1048576,MATCH($D8,'ASME II Tab 5A'!$5:$5,1)+1,0)-VLOOKUP($B13,'ASME II Tab 5A'!$1:$1048576,MATCH($D8,'ASME II Tab 5A'!$5:$5,1),0))/(INDEX('ASME II Tab 5A'!$5:$5,MATCH($D8,'ASME II Tab 5A'!$5:$5,1)+1)-INDEX('ASME II Tab 5A'!$5:$5,MATCH($D8,'ASME II Tab 5A'!$5:$5,1)))+VLOOKUP($B13,'ASME II Tab 5A'!$1:$1048576,MATCH($D8,'ASME II Tab 5A'!$5:$5,1)+1,0)-INDEX('ASME II Tab 5A'!$5:$5,MATCH($D8,'ASME II Tab 5A'!$5:$5,1)+1)*(VLOOKUP($B13,'ASME II Tab 5A'!$1:$1048576,MATCH($D8,'ASME II Tab 5A'!$5:$5,1)+1,0)-VLOOKUP($B13,'ASME II Tab 5A'!$1:$1048576,MATCH($D8,'ASME II Tab 5A'!$5:$5,1),0))/(INDEX('ASME II Tab 5A'!$5:$5,MATCH($D8,'ASME II Tab 5A'!$5:$5,1)+1)-INDEX('ASME II Tab 5A'!$5:$5,MATCH($D8,'ASME II Tab 5A'!$5:$5,1))) -> 94.3 | C20: N/mm2 | F20: =$D8*(VLOOKUP($F13,'ASME II Tab 5A'!$1:$1048576,MATCH($D8,'ASME II Tab 5A'!$5:$5,1)+1,0)-VLOOKUP($F13,'ASME II Tab 5A'!$1:$1048576,MATCH($D8,'ASME II Tab 5A'!$5:$5,1),0))/(INDEX('ASME II Tab 5A'!$5:$5,MATCH($D8,'ASME II Tab 5A'!$5:$5,1)+1)-INDEX('ASME II Tab 5A'!$5:$5,MATCH($D8,'ASME II Tab 5A'!$5:$5,1)))+VLOOKUP($F13,'ASME II Tab 5A'!$1:$1048576,MATCH($D8,'ASME II Tab 5A'!$5:$5,1)+1,0)-INDEX('ASME II Tab 5A'!$5:$5,MATCH($D8,'ASME II Tab 5A'!$5:$5,1)+1)*(VLOOKUP($F13,'ASME II Tab 5A'!$1:$1048576,MATCH($D8,'ASME II Tab 5A'!$5:$5,1)+1,0)-VLOOKUP($F13,'ASME II Tab 5A'!$1:$1048576,MATCH($D8,'ASME II Tab 5A'!$5:$5,1),0))/(INDEX('ASME II Tab 5A'!$5:$5,MATCH($D8,'ASME II Tab 5A'!$5:$5,1)+1)-INDEX('ASME II Tab 5A'!$5:$5,MATCH($D8,'ASME II Tab 5A'!$5:$5,1))) -> #N/A | G20: N/mm2 | K20: M2 Quantity | L20: =K2&"."&K20 -> 1.M2 Quantity | M20: =F135 -> 0
A21: Maximum Allowable Stress Head | B21: =$D8*(VLOOKUP($B14,'ASME II Tab 5A'!$1:$1048576,MATCH($D8,'ASME II Tab 5A'!$5:$5,1)+1,0)-VLOOKUP($B14,'ASME II Tab 5A'!$1:$1048576,MATCH($D8,'ASME II Tab 5A'!$5:$5,1),0))/(INDEX('ASME II Tab 5A'!$5:$5,MATCH($D8,'ASME II Tab 5A'!$5:$5,1)+1)-INDEX('ASME II Tab 5A'!$5:$5,MATCH($D8,'ASME II Tab 5A'!$5:$5,1)))+VLOOKUP($B14,'ASME II Tab 5A'!$1:$1048576,MATCH($D8,'ASME II Tab 5A'!$5:$5,1)+1,0)-INDEX('ASME II Tab 5A'!$5:$5,MATCH($D8,'ASME II Tab 5A'!$5:$5,1)+1)*(VLOOKUP($B14,'ASME II Tab 5A'!$1:$1048576,MATCH($D8,'ASME II Tab 5A'!$5:$5,1)+1,0)-VLOOKUP($B14,'ASME II Tab 5A'!$1:$1048576,MATCH($D8,'ASME II Tab 5A'!$5:$5,1),0))/(INDEX('ASME II Tab 5A'!$5:$5,MATCH($D8,'ASME II Tab 5A'!$5:$5,1)+1)-INDEX('ASME II Tab 5A'!$5:$5,MATCH($D8,'ASME II Tab 5A'!$5:$5,1))) -> 94.3 | C21: N/mm2 | F21: =$D8*(VLOOKUP($F14,'ASME II Tab 5A'!$1:$1048576,MATCH($D8,'ASME II Tab 5A'!$5:$5,1)+1,0)-VLOOKUP($F14,'ASME II Tab 5A'!$1:$1048576,MATCH($D8,'ASME II Tab 5A'!$5:$5,1),0))/(INDEX('ASME II Tab 5A'!$5:$5,MATCH($D8,'ASME II Tab 5A'!$5:$5,1)+1)-INDEX('ASME II Tab 5A'!$5:$5,MATCH($D8,'ASME II Tab 5A'!$5:$5,1)))+VLOOKUP($F14,'ASME II Tab 5A'!$1:$1048576,MATCH($D8,'ASME II Tab 5A'!$5:$5,1)+1,0)-INDEX('ASME II Tab 5A'!$5:$5,MATCH($D8,'ASME II Tab 5A'!$5:$5,1)+1)*(VLOOKUP($F14,'ASME II Tab 5A'!$1:$1048576,MATCH($D8,'ASME II Tab 5A'!$5:$5,1)+1,0)-VLOOKUP($F14,'ASME II Tab 5A'!$1:$1048576,MATCH($D8,'ASME II Tab 5A'!$5:$5,1),0))/(INDEX('ASME II Tab 5A'!$5:$5,MATCH($D8,'ASME II Tab 5A'!$5:$5,1)+1)-INDEX('ASME II Tab 5A'!$5:$5,MATCH($D8,'ASME II Tab 5A'!$5:$5,1))) -> #N/A | G21: N/mm2 | K21: M3 DN | L21: =K2&"."&K21 -> 1.M3 DN | M21: =C136 -> 0
K22: M3 Rating | L22: =K2&"."&K22 -> 1.M3 Rating | M22: =D136 -> 0
A23: Dimension: | K23: M3 Type | L23: =K2&"."&K23 -> 1.M3 Type | M23: =E136 -> 0
B24: SHELL 1 from plate | D24: SHELL 2 from plate | F24: SHELL 3 from piping | K24: M3 Quantity | L24: =K2&"."&K24 -> 1.M3 Quantity | M24: =F136 -> 0
A25: Nominal Diameter | F25: 8 | G25: inch | K25: Shell insulation thk 1 | L25: =K2&"."&K25 -> 1.Shell insulation thk 1 | M25: =B73 -> 100
A26: Shell Inside Diameter | B26: 800 | C26: mm | E26: mm | F26: =F27-2*F71 -> 202.74 | G26: mm | K26: Head insulation thk 1 | L26: =K2&"."&K26 -> 1.Head insulation thk 1 | M26: =B74 -> 100
A27: Shell Outside Diameter | B27: =B26+B67*2 -> 824 | C27: mm | D27: =D26+D67*2 -> 0 | E27: mm | F27: =IFERROR(VLOOKUP(F25,'Thickness Tab'!$1:$1048576,3,0),0) -> 219.1 | G27: mm | K27: Reducer insulation thk 1 | L27: =K2&"."&K27 -> 1.Reducer insulation thk 1 | M27: =B75 -> 100
A28: Tan / Tan | B28: 2100 | C28: mm | E28: mm | G28: mm | K28: Shell insulation area 1 | L28: =K2&"."&K28 -> 1.Shell insulation area 1 | M28: =B33 -> 6.752256
A29: Shell Unit Weight | B29: =(PI()*B28*(((B27/2)^2)-((B26/2)^2))*7860)/1000000000*1.05 -> 530.54019 | C29: kg | D29: =(PI()*D28*(((D27/2)^2)-((D26/2)^2))*7860)/1000000000*1.05 -> 0 | E29: kg | F29: =(PI()*F28*(((F27/2)^2)-((F26/2)^2))*7860)/1000000000*1.05 -> 0 | G29: kg | K29: Head insulation area 1 | L29: =K2&"."&K29 -> 1.Head insulation area 1 | M29: =B45 -> 1.7877402
A30: Shell Unit Volume | B30: =(PI()*((B26/2)^2)*B28)/1000000000 -> 1.0555751 | C30: m3 | D30: =(PI()*((D26/2)^2)*D28)/1000000000 -> 0 | E30: m3 | F30: =(PI()*((F26/2)^2)*F28)/1000000000 -> 0 | G30: m3 | K30: Reducer insulation area 1 | L30: =K2&"."&K30 -> 1.Reducer insulation area 1 | M30: =B58 -> 0
A31: Shell Unit External Surface | B31: =(B27*3.14*B28)/1000000 -> 5.433456 | C31: m2 | D31: =(D27*3.14*D28)/1000000 -> 0 | E31: m2 | F31: =(F27*3.14*F28)/1000000 -> 0 | G31: m2 | K31: Shell insulation thk 2 | L31: =K2&"."&K31 -> 1.Shell insulation thk 2 | M31: =D73 -> 0
A32: Shell Insulated Diameter | B32: =B27+2*B73 -> 1024 | C32: mm | D32: =D27+2*D73 -> 0 | E32: mm | F32: =F27+2*F73 -> 219.1 | G32: mm | K32: Head insulation thk 2 | L32: =K2&"."&K32 -> 1.Head insulation thk 2 | M32: =D74 -> 0
A33: Shell Unit Insulated Surface | B33: =(B32*3.14*B28)/1000000 -> 6.752256 | C33: m2 | D33: =(D32*3.14*D28)/1000000 -> 0 | E33: m2 | F33: =(F32*3.14*F28)/1000000 -> 0 | G33: m2 | K33: Reducer insulation thk 2 | L33: =K2&"."&K33 -> 1.Reducer insulation thk 2 | M33: =D75 -> 0
K34: Shell insulation area 2 | L34: =K2&"."&K34 -> 1.Shell insulation area 2 | M34: =D33 -> 0
B35: HEAD 1 | D35: HEAD 2 | F35: HEAD 3 from cap | K35: Head insulation area 2 | L35: =K2&"."&K35 -> 1.Head insulation area 2 | M35: =D45 -> 0
A36: Head Inside Diameter | B36: =B26 -> 800 | C36: mm | D36: =D26 -> 0 | E36: mm | F36: =F26 -> 202.74 | G36: mm | K36: Reducer insulation area 2 | L36: =K2&"."&K36 -> 1.Reducer insulation area 2 | M36: =D58 -> 0
A37: Head Outside Diameter | B37: =B36+2*B68 -> 824 | C37: mm | D37: =D36+2*D68 -> 0 | E37: mm | F37: =F36+2*F71 -> 219.1 | G37: mm | K37: Shell insulation thk 3 | L37: =K2&"."&K37 -> 1.Shell insulation thk 3 | M37: =F73 -> 0
A38: Head Height | B38: 300 | C38: mm | E38: mm | K38: Head insulation thk 3 | L38: =K2&"."&K38 -> 1.Head insulation thk 3 | M38: =F74 -> 0
A39: Heads Quantity | B39: 1 | K39: Reducer insulation thk 3 | L39: =K2&"."&K39 -> 1.Reducer insulation thk 3 | M39: =F75 -> 0
A40: Gap | B40: 0 | C40: mm | D40: 0 | E40: mm | F40: 0 | G40: mm | K40: Shell insulation area 3 | L40: =K2&"."&K40 -> 1.Shell insulation area 3 | M40: =F33 -> 0
...

Sheet Proposal Cost Report
A1: Cost Summary
A2: Pos. | B2: Cost type code | C2: Description | D2: U.M. | E2: Quanity | F2: Unit Cost | G2: Cost % | H2: Total Cost | I2: Note | K2: =List!$BJ$2 -> ENGINEERING | L2: =List!$BJ$3 -> EQUIPMENT | M2: =List!$BJ$4 -> PACKAGES | N2: =List!$BJ$5 -> MACHINERY | O2: =List!$BJ$6 -> MANUAL VALVES | P2: =List!$BJ$7 -> INSTRUMENTATION | Q2: =List!$BJ$8 -> ELECTRICA EQUIPMENT | R2: =List!$BJ$9 -> PIPE & FITTINGS | S2: =List!$BJ$10 -> STRUCTURES | T2: =List!$BJ$11 -> FABRICATION / ASSEMBLING /TESTS | U2: =List!$BJ$12 -> PACKING & SHIPMENT | V2: =List!$BJ$13 -> SITE ACTIVITIES | W2: =List!$BJ$14 -> SPARE PARTS | X2: =List!$BJ$15 -> OTHER COSTS | Y2: =List!$BJ$16 -> CONTINGENCY
F3: €/U.M. | G3: % | H3: €
A4: 1 | B4: STRUCTURES | C4: Skid Structures Supply | D4: kg | E4: =SUM('Module Fabrication Price List'!J4:J5,'Module Fabrication Price List'!J7:J13) -> 14343.807 | F4: =IFERROR(H4/E4,0) -> 4.0760616 | G4: =IFERROR(H4/$I$42,0) -> 0.048735985 | H4: =SUM('Module Fabrication Price List'!L4:L5,'Module Fabrication Price List'!L7:L13) -> 58466.241 | K4: =IF($B4=K$2,1,0) -> 0 | L4: =IF($B4=L$2,1,0) -> 0 | M4: =IF($B4=M$2,1,0) -> 0 | N4: =IF($B4=N$2,1,0) -> 0 | O4: =IF($B4=O$2,1,0) -> 0 | P4: =IF($B4=P$2,1,0) -> 0 | Q4: =IF($B4=Q$2,1,0) -> 0 | R4: =IF($B4=R$2,1,0) -> 0 | ... Y4: =IF($B4=Y$2,1,0) -> 0
A5: 2 | B5: STRUCTURES | C5: Aux. Structure Supply | D5: kg | E5: ='Module Fabrication Price List'!J6 -> 0 | F5: =IFERROR(H5/E5,0) -> 0 | G5: =IFERROR(H5/$I$42,0) -> 0 | H5: ='Module Fabrication Price List'!L6 -> 0 | K5: =IF($B5=K$2,1,0) -> 0 | L5: =IF($B5=L$2,1,0) -> 0 | M5: =IF($B5=M$2,1,0) -> 0 | N5: =IF($B5=N$2,1,0) -> 0 | O5: =IF($B5=O$2,1,0) -> 0 | P5: =IF($B5=P$2,1,0) -> 0 | Q5: =IF($B5=Q$2,1,0) -> 0 | R5: =IF($B5=R$2,1,0) -> 0 | ... Y5: =IF($B5=Y$2,1,0) -> 0
A6: 3 | B6: FABRICATION / ASSEMBLING /TESTS | C6: Skid Structures Fabrication | D6: kg | E6: =E4 -> 14343.807 | F6: =IFERROR(H6/E6,0) -> 3.8157839 | G6: =IFERROR(H6/$I$42,0) -> 0.045623939 | H6: =SUM('Module Fabrication Price List'!L15:L16,'Module Fabrication Price List'!L18:L24) -> 54732.868 | K6: =IF($B6=K$2,1,0) -> 0 | L6: =IF($B6=L$2,1,0) -> 0 | M6: =IF($B6=M$2,1,0) -> 0 | N6: =IF($B6=N$2,1,0) -> 0 | O6: =IF($B6=O$2,1,0) -> 0 | P6: =IF($B6=P$2,1,0) -> 0 | Q6: =IF($B6=Q$2,1,0) -> 0 | R6: =IF($B6=R$2,1,0) -> 0 | ... Y6: =IF($B6=Y$2,1,0) -> 0
A7: 4 | B7: FABRICATION / ASSEMBLING /TESTS | C7: Aux. Structure Fabrication | D7: kg | E7: =E5 -> 0 | F7: =IFERROR(H7/E7,0) -> 0 | G7: =IFERROR(H7/$I$42,0) -> 0 | H7: ='Module Fabrication Price List'!L17 -> 0 | K7: =IF($B7=K$2,1,0) -> 0 | L7: =IF($B7=L$2,1,0) -> 0 | M7: =IF($B7=M$2,1,0) -> 0 | N7: =IF($B7=N$2,1,0) -> 0 | O7: =IF($B7=O$2,1,0) -> 0 | P7: =IF($B7=P$2,1,0) -> 0 | Q7: =IF($B7=Q$2,1,0) -> 0 | R7: =IF($B7=R$2,1,0) -> 0 | ... Y7: =IF($B7=Y$2,1,0) -> 0
A8: 5 | B8: PIPE & FITTINGS | C8: Carbon Steel Piping Supply | D8: kg | E8: =SUMPRODUCT('Piping Material List'!$U$3:$U$96,'Piping Material List'!$DI$3:$DI$96) -> 495.66779 | F8: =IFERROR(H8/E8,0) -> 3 | G8: =IFERROR(H8/$I$42,0) -> 0.0012395285 | H8: =SUMPRODUCT('Piping Material List'!$W$3:$W$96,'Piping Material List'!$DI$3:$DI$96) -> 1487.0034 | K8: =IF($B8=K$2,1,0) -> 0 | L8: =IF($B8=L$2,1,0) -> 0 | M8: =IF($B8=M$2,1,0) -> 0 | N8: =IF($B8=N$2,1,0) -> 0 | O8: =IF($B8=O$2,1,0) -> 0 | P8: =IF($B8=P$2,1,0) -> 0 | Q8: =IF($B8=Q$2,1,0) -> 0 | R8: =IF($B8=R$2,1,0) -> 1 | ... Y8: =IF($B8=Y$2,1,0) -> 0
A9: 6 | B9: PIPE & FITTINGS | C9: Stainless Steel Piping Supply | D9: kg | E9: =SUMPRODUCT('Piping Material List'!$U$3:$U$96,'Piping Material List'!$DK$3:$DK$96) -> 2842.7054 | F9: =IFERROR(H9/E9,0) -> 15 | G9: =IFERROR(H9/$I$42,0) -> 0.035544113 | H9: =SUMPRODUCT('Piping Material List'!$W$3:$W$96,'Piping Material List'!$DK$3:$DK$96) -> 42640.581 | K9: =IF($B9=K$2,1,0) -> 0 | L9: =IF($B9=L$2,1,0) -> 0 | M9: =IF($B9=M$2,1,0) -> 0 | N9: =IF($B9=N$2,1,0) -> 0 | O9: =IF($B9=O$2,1,0) -> 0 | P9: =IF($B9=P$2,1,0) -> 0 | Q9: =IF($B9=Q$2,1,0) -> 0 | R9: =IF($B9=R$2,1,0) -> 1 | ... Y9: =IF($B9=Y$2,1,0) -> 0
A10: 7 | B10: PIPE & FITTINGS | C10: Duplex Stainless Steel Piping Supply | D10: kg | E10: =SUMPRODUCT('Piping Material List'!$U$3:$U$96,'Piping Material List'!$DL$3:$DL$96) -> 0 | F10: =IFERROR(H10/E10,0) -> 0 | G10: =IFERROR(#REF!/$I$42,0) -> 0 | H10: =SUMPRODUCT('Piping Material List'!$W$3:$W$96,'Piping Material List'!$DL$3:$DL$96) -> 0 | K10: =IF($B10=K$2,1,0) -> 0 | L10: =IF($B10=L$2,1,0) -> 0 | M10: =IF($B10=M$2,1,0) -> 0 | N10: =IF($B10=N$2,1,0) -> 0 | O10: =IF($B10=O$2,1,0) -> 0 | P10: =IF($B10=P$2,1,0) -> 0 | Q10: =IF($B10=Q$2,1,0) -> 0 | R10: =IF($B10=R$2,1,0) -> 1 | ... Y10: =IF($B10=Y$2,1,0) -> 0
A11: 8 | B11: PIPE & FITTINGS | C11: Incoloy 625/685 Piping Supply | D11: kg | E11: =SUMPRODUCT('Piping Material List'!$U$3:$U$96,'Piping Material List'!$DM$3:$DM$96) -> 0 | F11: =IFERROR(H11/E11,0) -> 0 | G11: =IFERROR(#REF!/$I$42,0) -> 0 | H11: =SUMPRODUCT('Piping Material List'!$W$3:$W$96,'Piping Material List'!$DM$3:$DM$96) -> 0 | K11: =IF($B11=K$2,1,0) -> 0 | L11: =IF($B11=L$2,1,0) -> 0 | M11: =IF($B11=M$2,1,0) -> 0 | N11: =IF($B11=N$2,1,0) -> 0 | O11: =IF($B11=O$2,1,0) -> 0 | P11: =IF($B11=P$2,1,0) -> 0 | Q11: =IF($B11=Q$2,1,0) -> 0 | R11: =IF($B11=R$2,1,0) -> 1 | ... Y11: =IF($B11=Y$2,1,0) -> 0
A12: 9 | B12: FABRICATION / ASSEMBLING /TESTS | C12: Carbon Steel Piping Fabrication | D12: d-inches | E12: =SUMPRODUCT('Piping Material List'!$AG$3:$AG$96,'Piping Material List'!$DI$3:$DI$96) -> 284.8 | F12: =IFERROR(H12/E12,0) -> 15 | G12: =IFERROR(H12/$I$42,0) -> 0.0035610315 | H12: ='Module Fabrication Price List'!$L$27 -> 4272 | K12: =IF($B12=K$2,1,0) -> 0 | L12: =IF($B12=L$2,1,0) -> 0 | M12: =IF($B12=M$2,1,0) -> 0 | N12: =IF($B12=N$2,1,0) -> 0 | O12: =IF($B12=O$2,1,0) -> 0 | P12: =IF($B12=P$2,1,0) -> 0 | Q12: =IF($B12=Q$2,1,0) -> 0 | R12: =IF($B12=R$2,1,0) -> 0 | ... Y12: =IF($B12=Y$2,1,0) -> 0
A13: 10 | B13: FABRICATION / ASSEMBLING /TESTS | C13: Stainless Steel Piping Fabrication | D13: d-inches | E13: =SUMPRODUCT('Piping Material List'!$AG$3:$AG$96,'Piping Material List'!$DK$3:$DK$96) -> 1372.8 | F13: =IFERROR(H13/E13,0) -> 20 | G13: =IFERROR(H13/$I$42,0) -> 0.022886629 | H13: ='Module Fabrication Price List'!$L$57 -> 27456 | K13: =IF($B13=K$2,1,0) -> 0 | L13: =IF($B13=L$2,1,0) -> 0 | M13: =IF($B13=M$2,1,0) -> 0 | N13: =IF($B13=N$2,1,0) -> 0 | O13: =IF($B13=O$2,1,0) -> 0 | P13: =IF($B13=P$2,1,0) -> 0 | Q13: =IF($B13=Q$2,1,0) -> 0 | R13: =IF($B13=R$2,1,0) -> 0 | ... Y13: =IF($B13=Y$2,1,0) -> 0
A14: 11 | B14: FABRICATION / ASSEMBLING /TESTS | C14: Duplex Stainless Steel Piping Fabrication | D14: d-inches | E14: =SUMPRODUCT('Piping Material List'!$AG$3:$AG$96,'Piping Material List'!$DL$3:$DL$96) -> 0 | F14: =IFERROR(H14/E14,0) -> 0 | G14: =IFERROR(H14/$I$42,0) -> 0 | H14: ='Module Fabrication Price List'!$L$87 -> 0 | K14: =IF($B14=K$2,1,0) -> 0 | L14: =IF($B14=L$2,1,0) -> 0 | M14: =IF($B14=M$2,1,0) -> 0 | N14: =IF($B14=N$2,1,0) -> 0 | O14: =IF($B14=O$2,1,0) -> 0 | P14: =IF($B14=P$2,1,0) -> 0 | Q14: =IF($B14=Q$2,1,0) -> 0 | R14: =IF($B14=R$2,1,0) -> 0 | ... Y14: =IF($B14=Y$2,1,0) -> 0
A15: 12 | B15: FABRICATION / ASSEMBLING /TESTS | C15: Incoloy 625/685 Piping Fabrication | D15: d-inches | E15: =SUMPRODUCT('Piping Material List'!$AG$3:$AG$96,'Piping Material List'!$DM$3:$DM$96) -> 0 | F15: =IFERROR(H15/E15,0) -> 0 | G15: =IFERROR(H15/$I$42,0) -> 0 | H15: ='Module Fabrication Price List'!$L$117 -> 0 | K15: =IF($B15=K$2,1,0) -> 0 | L15: =IF($B15=L$2,1,0) -> 0 | M15: =IF($B15=M$2,1,0) -> 0 | N15: =IF($B15=N$2,1,0) -> 0 | O15: =IF($B15=O$2,1,0) -> 0 | P15: =IF($B15=P$2,1,0) -> 0 | Q15: =IF($B15=Q$2,1,0) -> 0 | R15: =IF($B15=R$2,1,0) -> 0 | ... Y15: =IF($B15=Y$2,1,0) -> 0
A16: 13 | B16: FABRICATION / ASSEMBLING /TESTS | C16: NDE & Hydrotest & PWHT | D16: set | E16: 1 | F16: =IFERROR(H16/E16,0) -> 10379.56 | G16: =IFERROR(H16/$I$42,0) -> 0.0086521394 | H16: =SUM('Module Fabrication Price List'!$L$148,'Module Fabrication Price List'!$L$176,'Module Fabrication Price List'!$L$204,'Module Fabrication Price List'!$L$232,'Module Fabrication Price List'!$L$260,'Module Fabrication Price List'!$L$262,'Module Fabrication Price List'!$L$265,'Module Fabrication Price List'!$L$270) -> 10379.56 | K16: =IF($B16=K$2,1,0) -> 0 | L16: =IF($B16=L$2,1,0) -> 0 | M16: =IF($B16=M$2,1,0) -> 0 | N16: =IF($B16=N$2,1,0) -> 0 | O16: =IF($B16=O$2,1,0) -> 0 | P16: =IF($B16=P$2,1,0) -> 0 | Q16: =IF($B16=Q$2,1,0) -> 0 | R16: =IF($B16=R$2,1,0) -> 0 | ... Y16: =IF($B16=Y$2,1,0) -> 0
A17: 14 | B17: MANUAL VALVES | C17: Manual Valve Supply | D17: cad | E17: =SUM('Valve List'!AV3:AV99) -> 40 | F17: =IFERROR(H17/E17,0) -> 1578 | G17: =IFERROR(H17/$I$42,0) -> 0.052615241 | H17: =SUM('Valve List'!BA3:BA99) -> 63120 | K17: =IF($B17=K$2,1,0) -> 0 | L17: =IF($B17=L$2,1,0) -> 0 | M17: =IF($B17=M$2,1,0) -> 0 | N17: =IF($B17=N$2,1,0) -> 0 | O17: =IF($B17=O$2,1,0) -> 1 | P17: =IF($B17=P$2,1,0) -> 0 | Q17: =IF($B17=Q$2,1,0) -> 0 | R17: =IF($B17=R$2,1,0) -> 0 | ... Y17: =IF($B17=Y$2,1,0) -> 0
A18: 15 | B18: INSTRUMENTATION | C18: Instrumentation Supply | D18: set | E18: 1 | F18: =IFERROR(H18/E18,0) -> 296402.8 | G18: =IFERROR(H18/$I$42,0) -> 0.2470739 | H18: =SUM('Instrument List'!AG4:AG67) -> 296402.8 | K18: =IF($B18=K$2,1,0) -> 0 | L18: =IF($B18=L$2,1,0) -> 0 | M18: =IF($B18=M$2,1,0) -> 0 | N18: =IF($B18=N$2,1,0) -> 0 | O18: =IF($B18=O$2,1,0) -> 0 | P18: =IF($B18=P$2,1,0) -> 1 | Q18: =IF($B18=Q$2,1,0) -> 0 | R18: =IF($B18=R$2,1,0) -> 0 | ... Y18: =IF($B18=Y$2,1,0) -> 0
A19: 16 | B19: EQUIPMENT | C19: Equipment Supply | D19: set | E19: 1 | F19: =IFERROR(H19/E19,0) -> 325800 | G19: =IFERROR(H19/$I$42,0) -> 0.27157867 | H19: ='Equip&Mach List'!V1 -> 325800 | K19: =IF($B19=K$2,1,0) -> 0 | L19: =IF($B19=L$2,1,0) -> 1 | M19: =IF($B19=M$2,1,0) -> 0 | N19: =IF($B19=N$2,1,0) -> 0 | O19: =IF($B19=O$2,1,0) -> 0 | P19: =IF($B19=P$2,1,0) -> 0 | Q19: =IF($B19=Q$2,1,0) -> 0 | R19: =IF($B19=R$2,1,0) -> 0 | ... Y19: =IF($B19=Y$2,1,0) -> 0
A20: 17 | B20: MACHINERY | C20: Machinery Supply | D20: set | E20: 1 | F20: =IFERROR(H20/E20,0) -> 163000 | G20: =IFERROR(H20/$I$42,0) -> 0.13587269 | H20: ='Equip&Mach List'!V30 -> 163000 | K20: =IF($B20=K$2,1,0) -> 0 | L20: =IF($B20=L$2,1,0) -> 0 | M20: =IF($B20=M$2,1,0) -> 0 | N20: =IF($B20=N$2,1,0) -> 1 | O20: =IF($B20=O$2,1,0) -> 0 | P20: =IF($B20=P$2,1,0) -> 0 | Q20: =IF($B20=Q$2,1,0) -> 0 | R20: =IF($B20=R$2,1,0) -> 0 | ... Y20: =IF($B20=Y$2,1,0) -> 0
A21: 18 | B21: OTHER COSTS | C21: Accessiories | D21: set | E21: 1 | F21: =IFERROR(H21/E21,0) -> 3000 | G21: =IFERROR(H21/$I$42,0) -> 0.0025007244 | H21: ='Equip&Mach List'!AA5 -> 3000 | K21: =IF($B21=K$2,1,0) -> 0 | L21: =IF($B21=L$2,1,0) -> 0 | M21: =IF($B21=M$2,1,0) -> 0 | N21: =IF($B21=N$2,1,0) -> 0 | O21: =IF($B21=O$2,1,0) -> 0 | P21: =IF($B21=P$2,1,0) -> 0 | Q21: =IF($B21=Q$2,1,0) -> 0 | R21: =IF($B21=R$2,1,0) -> 0 | ... Y21: =IF($B21=Y$2,1,0) -> 0
A22: 19 | B22: FABRICATION / ASSEMBLING /TESTS | C22: Skid Structures Installation | D22: kg | E22: =E4 -> 14343.807 | F22: =IFERROR(H22/E22,0) -> 0.45080804 | G22: =IFERROR(H22/$I$42,0) -> 0.0053901477 | H22: ='Module Fabrication Price List'!L274 -> 6466.3036 | K22: =IF($B22=K$2,1,0) -> 0 | L22: =IF($B22=L$2,1,0) -> 0 | M22: =IF($B22=M$2,1,0) -> 0 | N22: =IF($B22=N$2,1,0) -> 0 | O22: =IF($B22=O$2,1,0) -> 0 | P22: =IF($B22=P$2,1,0) -> 0 | Q22: =IF($B22=Q$2,1,0) -> 0 | R22: =IF($B22=R$2,1,0) -> 0 | ... Y22: =IF($B22=Y$2,1,0) -> 0
A23: 20 | B23: FABRICATION / ASSEMBLING /TESTS | C23: Piping Installation | D23: kg | E23: =SUM('Module Fabrication Price List'!J281:J298) -> 3338.3732 | F23: =IFERROR(H23/E23,0) -> 0.5 | G23: =IFERROR(H23/$I$42,0) -> 0.0013913919 | H23: ='Module Fabrication Price List'!L280 -> 1669.1866 | K23: =IF($B23=K$2,1,0) -> 0 | L23: =IF($B23=L$2,1,0) -> 0 | M23: =IF($B23=M$2,1,0) -> 0 | N23: =IF($B23=N$2,1,0) -> 0 | O23: =IF($B23=O$2,1,0) -> 0 | P23: =IF($B23=P$2,1,0) -> 0 | Q23: =IF($B23=Q$2,1,0) -> 0 | R23: =IF($B23=R$2,1,0) -> 0 | ... Y23: =IF($B23=Y$2,1,0) -> 0
A24: 21 | B24: FABRICATION / ASSEMBLING /TESTS | C24: Valve Installation | D24: kg | E24: =SUM('Module Fabrication Price List'!J300:J317) -> 2089.5 | F24: =IFERROR(H24/E24,0) -> 0.53374013 | G24: =IFERROR(H24/$I$42,0) -> 0.00092964429 | H24: ='Module Fabrication Price List'!L299 -> 1115.25 | K24: =IF($B24=K$2,1,0) -> 0 | L24: =IF($B24=L$2,1,0) -> 0 | M24: =IF($B24=M$2,1,0) -> 0 | N24: =IF($B24=N$2,1,0) -> 0 | O24: =IF($B24=O$2,1,0) -> 0 | P24: =IF($B24=P$2,1,0) -> 0 | Q24: =IF($B24=Q$2,1,0) -> 0 | R24: =IF($B24=R$2,1,0) -> 0 | ... Y24: =IF($B24=Y$2,1,0) -> 0
A25: 22 | B25: FABRICATION / ASSEMBLING /TESTS | C25: Equipment Installation | D25: kg | E25: =SUM('Module Fabrication Price List'!J319:J338) -> 14450 | F25: =IFERROR(H25/E25,0) -> 0.9766436 | G25: =IFERROR(H25/$I$42,0) -> 0.011763824 | H25: ='Module Fabrication Price List'!L318 -> 14112.5 | K25: =IF($B25=K$2,1,0) -> 0 | L25: =IF($B25=L$2,1,0) -> 0 | M25: =IF($B25=M$2,1,0) -> 0 | N25: =IF($B25=N$2,1,0) -> 0 | O25: =IF($B25=O$2,1,0) -> 0 | P25: =IF($B25=P$2,1,0) -> 0 | Q25: =IF($B25=Q$2,1,0) -> 0 | R25: =IF($B25=R$2,1,0) -> 0 | ... Y25: =IF($B25=Y$2,1,0) -> 0
A26: 23 | B26: FABRICATION / ASSEMBLING /TESTS | C26: Machinery Installation | D26: kg | E26: =SUM('Module Fabrication Price List'!J340:J359) -> 3650 | F26: =IFERROR(H26/E26,0) -> 0.82876712 | G26: =IFERROR(H26/$I$42,0) -> 0.0025215637 | H26: ='Module Fabrication Price List'!L339 -> 3025 | K26: =IF($B26=K$2,1,0) -> 0 | L26: =IF($B26=L$2,1,0) -> 0 | M26: =IF($B26=M$2,1,0) -> 0 | N26: =IF($B26=N$2,1,0) -> 0 | O26: =IF($B26=O$2,1,0) -> 0 | P26: =IF($B26=P$2,1,0) -> 0 | Q26: =IF($B26=Q$2,1,0) -> 0 | R26: =IF($B26=R$2,1,0) -> 0 | ... Y26: =IF($B26=Y$2,1,0) -> 0
A27: 24 | B27: FABRICATION / ASSEMBLING /TESTS | C27: Assembling&Dismalting | D27: cad | E27: ='Module Fabrication Price List'!J362 -> 1 | F27: =IFERROR(H27/E27,0) -> 0 | G27: =IFERROR(H27/$I$42,0) -> 0 | H27: ='Module Fabrication Price List'!L361 -> 0 | K27: =IF($B27=K$2,1,0) -> 0 | L27: =IF($B27=L$2,1,0) -> 0 | M27: =IF($B27=M$2,1,0) -> 0 | N27: =IF($B27=N$2,1,0) -> 0 | O27: =IF($B27=O$2,1,0) -> 0 | P27: =IF($B27=P$2,1,0) -> 0 | Q27: =IF($B27=Q$2,1,0) -> 0 | R27: =IF($B27=R$2,1,0) -> 0 | ... Y27: =IF($B27=Y$2,1,0) -> 0
A28: 25 | B28: PACKING & SHIPMENT | C28: Packing | D28: m3 | E28: =SUM('Module Fabrication Price List'!J365:J439) -> 245.8 | F28: =IFERROR(H28/E28,0) -> 49.796583 | G28: =IFERROR(H28/$I$42,0) -> 0.010202955 | H28: ='Module Fabrication Price List'!L363 -> 12240 | K28: =IF($B28=K$2,1,0) -> 0 | L28: =IF($B28=L$2,1,0) -> 0 | M28: =IF($B28=M$2,1,0) -> 0 | N28: =IF($B28=N$2,1,0) -> 0 | O28: =IF($B28=O$2,1,0) -> 0 | P28: =IF($B28=P$2,1,0) -> 0 | Q28: =IF($B28=Q$2,1,0) -> 0 | R28: =IF($B28=R$2,1,0) -> 0 | ... Y28: =IF($B28=Y$2,1,0) -> 0
A29: 26 | B29: FABRICATION / ASSEMBLING /TESTS | C29: Collaudo | D29: set | E29: 1 | F29: 1500 | G29: =IFERROR(H29/$I$42,0) -> 0.0012503622 | H29: =F29*E29 -> 1500 | K29: =IF($B29=K$2,1,0) -> 0 | L29: =IF($B29=L$2,1,0) -> 0 | M29: =IF($B29=M$2,1,0) -> 0 | N29: =IF($B29=N$2,1,0) -> 0 | O29: =IF($B29=O$2,1,0) -> 0 | P29: =IF($B29=P$2,1,0) -> 0 | Q29: =IF($B29=Q$2,1,0) -> 0 | R29: =IF($B29=R$2,1,0) -> 0 | ... Y29: =IF($B29=Y$2,1,0) -> 0
A30: 27 | B30: FABRICATION / ASSEMBLING /TESTS | C30: Instrument assembly | D30: h | E30: =SUM('Instrument List'!$AC:$AC) -> 272.5 | F30: 30 | G30: =IFERROR(H30/$I$42,0) -> 0.0068144739 | H30: =F30*E30 -> 8175 | I30: ESTERNI | K30: =IF($B30=K$2,1,0) -> 0 | L30: =IF($B30=L$2,1,0) -> 0 | M30: =IF($B30=M$2,1,0) -> 0 | N30: =IF($B30=N$2,1,0) -> 0 | O30: =IF($B30=O$2,1,0) -> 0 | P30: =IF($B30=P$2,1,0) -> 0 | Q30: =IF($B30=Q$2,1,0) -> 0 | R30: =IF($B30=R$2,1,0) -> 0 | ... Y30: =IF($B30=Y$2,1,0) -> 0
A31: 28 | B31: FABRICATION / ASSEMBLING /TESTS | C31: Painting | D31: m2 | E31: ='Proposal Quantity Report'!$B$40 -> 567.33573 | F31: =IFERROR(H31/E31,0) -> 43.757348 | G31: =IFERROR(H31/$I$42,0) -> 0.020693583 | H31: ='Proposal Quantity Report'!$I$40 -> 24825.107 | I31: STD | K31: =IF($B31=K$2,1,0) -> 0 | L31: =IF($B31=L$2,1,0) -> 0 | M31: =IF($B31=M$2,1,0) -> 0 | N31: =IF($B31=N$2,1,0) -> 0 | O31: =IF($B31=O$2,1,0) -> 0 | P31: =IF($B31=P$2,1,0) -> 0 | Q31: =IF($B31=Q$2,1,0) -> 0 | R31: =IF($B31=R$2,1,0) -> 0 | ... Y31: =IF($B31=Y$2,1,0) -> 0
A32: 29 | B32: FABRICATION / ASSEMBLING /TESTS | C32: Insultation | D32: m2 | F32: 16267 | G32: =IFERROR(H32/$I$42,0) -> 0.013559761 | H32: 16267 | K32: =IF($B32=K$2,1,0) -> 0 | L32: =IF($B32=L$2,1,0) -> 0 | M32: =IF($B32=M$2,1,0) -> 0 | N32: =IF($B32=N$2,1,0) -> 0 | O32: =IF($B32=O$2,1,0) -> 0 | P32: =IF($B32=P$2,1,0) -> 0 | Q32: =IF($B32=Q$2,1,0) -> 0 | R32: =IF($B32=R$2,1,0) -> 0 | ... Y32: =IF($B32=Y$2,1,0) -> 0
C33: Trasporti Interni | D33: set | E33: 1 | F33: 3000 | G33: =IFERROR(H33/$I$42,0) -> 0.0025007244 | H33: =F33*E33 -> 3000
A34: 30 | B34: ENGINEERING | C34: ENGINEERING ESTERNA | D34: set | E34: 1 | F34: 25000 | G34: =IFERROR(H34/$I$42,0) -> 0.02083937 | H34: =F34*E34 -> 25000 | I34: COSTO ING. DIVISO PER DUE UNITA' | K34: =IF($B34=K$2,1,0) -> 1 | L34: =IF($B34=L$2,1,0) -> 0 | M34: =IF($B34=M$2,1,0) -> 0 | N34: =IF($B34=N$2,1,0) -> 0 | O34: =IF($B34=O$2,1,0) -> 0 | P34: =IF($B34=P$2,1,0) -> 0 | Q34: =IF($B34=Q$2,1,0) -> 0 | R34: =IF($B34=R$2,1,0) -> 0 | ... Y34: =IF($B34=Y$2,1,0) -> 0
A35: 31 | B35: OTHER COSTS | C35: Catalizzatore DEOXO | D35: set | E35: 1 | G35: =IFERROR(H35/$I$42,0) -> 0 | H35: =F35*E35 -> 0 | K35: =IF($B35=K$2,1,0) -> 0 | L35: =IF($B35=L$2,1,0) -> 0 | M35: =IF($B35=M$2,1,0) -> 0 | N35: =IF($B35=N$2,1,0) -> 0 | O35: =IF($B35=O$2,1,0) -> 0 | P35: =IF($B35=P$2,1,0) -> 0 | Q35: =IF($B35=Q$2,1,0) -> 0 | R35: =IF($B35=R$2,1,0) -> 0 | ... Y35: =IF($B35=Y$2,1,0) -> 0
A36: 32 | B36: OTHER COSTS | C36: Setacci Molecolari Dryer | D36: set | E36: 6 | G36: =IFERROR(H36/$I$42,0) -> 0 | H36: =F36*E36 -> 0 | I36: DUE CARICHE SETACCIO 5 ANNI GARANZIA | K36: =IF($B36=K$2,1,0) -> 0 | L36: =IF($B36=L$2,1,0) -> 0 | M36: =IF($B36=M$2,1,0) -> 0 | N36: =IF($B36=N$2,1,0) -> 0 | O36: =IF($B36=O$2,1,0) -> 0 | P36: =IF($B36=P$2,1,0) -> 0 | Q36: =IF($B36=Q$2,1,0) -> 0 | R36: =IF($B36=R$2,1,0) -> 0 | ... Y36: =IF($B36=Y$2,1,0) -> 0
A37: 34 | G37: =IFERROR(H37/$I$42,0) -> 0 | H37: =F37*E37 -> 0 | I37: COSTO ING. DIVISO PER DUE UNITA' | K37: =IF($B37=K$2,1,0) -> 0 | L37: =IF($B37=L$2,1,0) -> 0 | M37: =IF($B37=M$2,1,0) -> 0 | N37: =IF($B37=N$2,1,0) -> 0 | O37: =IF($B37=O$2,1,0) -> 0 | P37: =IF($B37=P$2,1,0) -> 0 | Q37: =IF($B37=Q$2,1,0) -> 0 | R37: =IF($B37=R$2,1,0) -> 0 | ... Y37: =IF($B37=Y$2,1,0) -> 0
A38: 35 | B38: ENGINEERING | C38: ENGINEERING INTERNA | D38: h | E38: 600 | F38: 40 | G38: =IFERROR(H38/$I$42,0) -> 0.020005795 | H38: =E38*F38 -> 24000 | I38: COSTO ING. DIVISO PER DUE UNITA' | K38: =IF($B38=K$2,1,0) -> 1 | L38: =IF($B38=L$2,1,0) -> 0 | M38: =IF($B38=M$2,1,0) -> 0 | N38: =IF($B38=N$2,1,0) -> 0 | O38: =IF($B38=O$2,1,0) -> 0 | P38: =IF($B38=P$2,1,0) -> 0 | Q38: =IF($B38=Q$2,1,0) -> 0 | R38: =IF($B38=R$2,1,0) -> 0 | ... Y38: =IF($B38=Y$2,1,0) -> 0
A39: 36 | B39: ENGINEERING | C39: QUALITA | D39: h | E39: 50 | F39: 45 | G39: =IFERROR(H39/$I$42,0) -> 0.0018755433 | H39: =E39*F39 -> 2250 | I39: COSTO ING. DIVISO PER DUE UNITA' | K39: =IF($B39=K$2,1,0) -> 1 | L39: =IF($B39=L$2,1,0) -> 0 | M39: =IF($B39=M$2,1,0) -> 0 | N39: =IF($B39=N$2,1,0) -> 0 | O39: =IF($B39=O$2,1,0) -> 0 | P39: =IF($B39=P$2,1,0) -> 0 | Q39: =IF($B39=Q$2,1,0) -> 0 | R39: =IF($B39=R$2,1,0) -> 0 | ... Y39: =IF($B39=Y$2,1,0) -> 0
A40: 37 | B40: ENGINEERING | C40: ACQUISTI | D40: h | E40: 50 | F40: 45 | G40: =IFERROR(H40/$I$42,0) -> 0.0018755433 | H40: =E40*F40 -> 2250 | I40: COSTO ING. DIVISO PER DUE UNITA' | K40: =IF($B40=K$2,1,0) -> 1 | L40: =IF($B40=L$2,1,0) -> 0 | M40: =IF($B40=M$2,1,0) -> 0 | N40: =IF($B40=N$2,1,0) -> 0 | O40: =IF($B40=O$2,1,0) -> 0 | P40: =IF($B40=P$2,1,0) -> 0 | Q40: =IF($B40=Q$2,1,0) -> 0 | R40: =IF($B40=R$2,1,0) -> 0 | ... Y40: =IF($B40=Y$2,1,0) -> 0
...

Sheet Cost Type
A1: PROG | B1: CAT1 | C1: CAT1_DESC | D1: CAT2 | E1: ARTICOLI (IT) | F1: ARTICOLI (EN) | G1: COST TYPE
A2: MA100 | B2: MA | C2: ENGINEERING | D2: Mechanical Vessel / Heater Eng. | E2: Progettazione vessel | F2: Vessel Engineering
A3: MA200 | B3: MA | C3: ENGINEERING | D3: Mechanical Eng. | E3: Progettazione piping Progettazione componenti meccanici Stress Analysis | F3: Piping Engineering Mechanical Components Engineering Stress Analysis
A4: MA300 | B4: MA | C4: ENGINEERING | D4: Elect./Instr. Eng. | E4: Progettazione elettro-strumentale Classificazione aree pericolose | F4: Instruments and Electrical Components Engineering Hazardous Area Classification
A5: MA400 | B5: MA | C5: ENGINEERING | D5: Process & Termal Calculation | E5: Ingegneria di base Ingegneria di processo | F5: Basic Engineering Process Engineering
A6: MA500 | B6: MA | C6: ENGINEERING | D6: Civil Engineering | E6: Progettazione Opere Civili
A7: MA600 | B7: MA | C7: ENGINEERING | D7: Project Manager | E7: PM
A8: MA610 | B8: MA | C8: ENGINEERING | D8: Project Engineering | E8: PE
A9: MA620 | B9: MA | C9: ENGINEERING | D9: Buyer | E9: Acquisti
A10: MA630 | B10: MA | C10: ENGINEERING | D10: Quality Control | E10: Qualità
A11: MA640 | B11: MA | C11: ENGINEERING | D11: Expediting
A12: MB110 | B12: MB | C12: EQUIPMENT | D12: Tanks | E12: Serbatoio accumulo condensa Serbatoio di accumulo circuito acqua Vaso di espansione circuito acqua | F12: Condensate tank Water tank Expansion tank
A13: MB111 | B13: MB | C13: EQUIPMENT | D13: Inlet Scrubber | E13: For proces Packages | F13: For proces Packages
A14: MB112 | B14: MB | C14: EQUIPMENT | D14: Outlet Scrubber | E14: For proces Packages | F14: For proces Packages
A15: MB113 | B15: MB | C15: EQUIPMENT | D15: Flash Drum | E15: For proces Packages | F15: For proces Packages
A16: MB114 | B16: MB | C16: EQUIPMENT | D16: Glycol Reboiler | E16: For proces Packages | F16: For proces Packages
A17: MB115 | B17: MB | C17: EQUIPMENT | D17: OVHD Vapours KO Drum | E17: For proces Packages | F17: For proces Packages
A18: MB116 | B18: MB | C18: EQUIPMENT | D18: Surge Drum | E18: For proces Packages | F18: For proces Packages
A19: MB120 | B19: MB | C19: EQUIPMENT | D19: Columns
A20: MB121 | B20: MB | C20: EQUIPMENT | D20: Dehydration Column | E20: For proces Packages | F20: For proces Packages
A21: MB122 | B21: MB | C21: EQUIPMENT | D21: Still Column | E21: For proces Packages | F21: For proces Packages
A22: MB123 | B22: MB | C22: EQUIPMENT | D22: Stripping Column | E22: For proces Packages | F22: For proces Packages
A23: MB130 | B23: MB | C23: EQUIPMENT | D23: Separators | F23: KO Drum Scrubber (Vane, cyclones, meshpad, …)
A24: MB140 | B24: MB | C24: EQUIPMENT | D24: Filter separators | E24: Filtri Separatori a cartuccia + Vane Filtri separatori a cicloni+cartuccia Filtri Separatori a cartuccia | F24: Cartridge + Vane Filter Separator Cyclones + Cartridge Filter Separator Cartridge Filter Separator
A25: MB150 | B25: MB | C25: EQUIPMENT | D25: Filters | E25: Filtro a cartuccie standard HFA / HF Filtri a cestello Filtri temporanei | F25: Standard cartridge filter HFA / HF Basket Filter Temporary Filter
A26: MB151 | B26: MB | C26: EQUIPMENT | D26: Glycol Filters | E26: For proces Packages | F26: For proces Packages
A27: MB152 | B27: MB | C27: EQUIPMENT | D27: Carbon Filters | E27: For proces Packages | F27: For proces Packages
A28: MB160 | B28: MB | C28: EQUIPMENT | D28: Pig Traps | E28: Trappole di lancio | F28: Pig launcher/receivers
A29: MB210 | B29: MB | C29: EQUIPMENT | D29: Shell & Tube Heat Exchanger | E29: Scambiatore a fascio tubiero standard KSI Scambiatore a fascio tubiero | F29: Tube Bundle heat exchanger KSI Tube Bundle heat exchanger
A30: MB211 | B30: MB | C30: EQUIPMENT | D30: Lean / Rich Heat Exchanger | E30: For proces Packages | F30: For proces Packages
A31: MB212 | B31: MB | C31: EQUIPMENT | D31: Reflux Condenser | E31: For proces Packages | F31: For proces Packages
A32: MB213 | B32: MB | C32: EQUIPMENT | D32: S&T OVHD Vapours Condenser | E32: For proces Packages | F32: For proces Packages
A33: MB214 | B33: MB | C33: EQUIPMENT | D33: S&T Lean Glycol Cooler | E33: For proces Packages | F33: For proces Packages
A34: MB220 | B34: MB | C34: EQUIPMENT | D34: Air Cooler
A35: MB221 | B35: MB | C35: EQUIPMENT | D35: Air Lean Glycol Cooler | E35: For proces Packages | F35: For proces Packages
A36: MB222 | B36: MB | C36: EQUIPMENT | D36: Air OVHD Vapours Condenser | E36: For proces Packages | F36: For proces Packages
A37: MB230 | B37: MB | C37: EQUIPMENT | D37: Plate Heat Exchanger
